2024-07-31 20:10:36,382 INFO    MainThread:897 [wandb_setup.py:_flush():76] Current SDK version is 0.17.5
2024-07-31 20:10:36,382 INFO    MainThread:897 [wandb_setup.py:_flush():76] Configure stats pid to 897
2024-07-31 20:10:36,382 INFO    MainThread:897 [wandb_setup.py:_flush():76] Loading settings from /root/.config/wandb/settings
2024-07-31 20:10:36,382 INFO    MainThread:897 [wandb_setup.py:_flush():76] Loading settings from /root/collaborative-stegosystem/collaborative-stegosystem/wandb/settings
2024-07-31 20:10:36,382 INFO    MainThread:897 [wandb_setup.py:_flush():76] Loading settings from environment variables: {}
2024-07-31 20:10:36,382 INFO    MainThread:897 [wandb_setup.py:_flush():76] Applying setup settings: {'_disable_service': False}
2024-07-31 20:10:36,382 INFO    MainThread:897 [wandb_setup.py:_flush():76] Inferring run settings from compute environment: {'program_relpath': 'main.py', 'program_abspath': '/root/collaborative-stegosystem/collaborative-stegosystem/main.py', 'program': '/root/collaborative-stegosystem/collaborative-stegosystem/main.py'}
2024-07-31 20:10:36,382 INFO    MainThread:897 [wandb_setup.py:_flush():76] Applying login settings: {}
2024-07-31 20:10:36,382 INFO    MainThread:897 [wandb_setup.py:_flush():76] Applying login settings: {'api_key': '***REDACTED***'}
2024-07-31 20:10:36,382 INFO    MainThread:897 [wandb_init.py:_log_setup():529] Logging user logs to /root/collaborative-stegosystem/collaborative-stegosystem/wandb/run-20240731_201036-n9bpng7x/logs/debug.log
2024-07-31 20:10:36,382 INFO    MainThread:897 [wandb_init.py:_log_setup():530] Logging internal logs to /root/collaborative-stegosystem/collaborative-stegosystem/wandb/run-20240731_201036-n9bpng7x/logs/debug-internal.log
2024-07-31 20:10:36,382 INFO    MainThread:897 [wandb_init.py:init():569] calling init triggers
2024-07-31 20:10:36,382 INFO    MainThread:897 [wandb_init.py:init():576] wandb.init called with sweep_config: {}
config: {'experiment': {'name': 'Collaborative Stegosystem', 'wandb_project': 'Collaborative Stegosystem', 'wandb_entity': 'chansmi'}, 'model': {'name': 'meta-llama/Meta-Llama-3.1-8B-Instruct', 'use_peft': True, 'lora_alpha': 16, 'lora_r': 16}, 'training': {'num_epochs': 10, 'batch_size': 4, 'learning_rate': '2e-5', 'max_grad_norm': 0.5, 'num_conversations_per_day': 3, 'max_conversation_length': 128}, 'environment': {'starting_budget': 1000000, 'num_trading_days': 252, 'target_stock': 'AAPL', 'target_stock_increase': 0.8874}, 'ppo': {'epsilon': 0.2, 'value_loss_coef': 0.5, 'entropy_coef': 0.01}}
2024-07-31 20:10:36,382 INFO    MainThread:897 [wandb_init.py:init():619] starting backend
2024-07-31 20:10:36,383 INFO    MainThread:897 [wandb_init.py:init():623] setting up manager
2024-07-31 20:10:36,387 INFO    MainThread:897 [backend.py:_multiprocessing_setup():105] multiprocessing start_methods=fork,spawn,forkserver, using: spawn
2024-07-31 20:10:36,388 INFO    MainThread:897 [wandb_init.py:init():631] backend started and connected
2024-07-31 20:10:36,396 INFO    MainThread:897 [wandb_init.py:init():720] updated telemetry
2024-07-31 20:10:36,401 INFO    MainThread:897 [wandb_init.py:init():753] communicating run to backend with 90.0 second timeout
2024-07-31 20:10:36,547 ERROR   MainThread:897 [wandb_init.py:init():779] encountered error: The API key you provided is either invalid or missing.  If the `WANDB_API_KEY` environment variable is set, make sure it is correct. Otherwise, to resolve this issue, you may try running the 'wandb login --relogin' command. If you are using a local server, make sure that you're using the correct hostname. If you're not sure, you can try logging in again using the 'wandb login --relogin --host [hostname]' command.(Error 401: Unauthorized)
2024-07-31 20:10:36,547 ERROR   MainThread:897 [wandb_init.py:init():1191] error in wandb.init()
Traceback (most recent call last):
  File "/usr/local/lib/python3.10/dist-packages/wandb/sdk/wandb_init.py", line 1181, in init
    return wi.init()
  File "/usr/local/lib/python3.10/dist-packages/wandb/sdk/wandb_init.py", line 785, in init
    raise error
wandb.errors.AuthenticationError: The API key you provided is either invalid or missing.  If the `WANDB_API_KEY` environment variable is set, make sure it is correct. Otherwise, to resolve this issue, you may try running the 'wandb login --relogin' command. If you are using a local server, make sure that you're using the correct hostname. If you're not sure, you can try logging in again using the 'wandb login --relogin --host [hostname]' command.(Error 401: Unauthorized)
2024-07-31 20:10:37,649 WARNING MsgRouterThr:897 [router.py:message_loop():77] message_loop has been closed
